<?xml version="1.0"?>
<!-- Author: Ross Hartley
	 Email:  rosshart@umich.edu
     Date:   04/24/2016   -->
<robot name="cassie" 
  xmlns:xacro="http://ros.org/wiki/xacro">
  
  <!-- Properties -->
  <xacro:property name="black_RGB" value="0.1 0.1 0.1 1" />
  <xacro:property name="grey_RGB" value="0.35 0.35 0.35 1" />
  <xacro:property name="orange_RGB" value=".9569 .5372 .2588 1" />
  <xacro:property name="blue_RGB" value=".0157 .1176 .2588 1" />
  <xacro:property name="maize_RGB" value=".9451 .7686 0 1" />
  <xacro:property name="light_grey_RGB" value="0.75 0.75 0.75 1" />

  <!-- Links -->
  <xacro:vectorNav />
  <xacro:pelvis cname="grey" color="${grey_RGB}" />
  <xacro:pelvis_abduction side="left" cname="light_grey" color="${light_grey_RGB}" stl_ext=""/>
  <xacro:pelvis_rotation side="left" cname="light_grey" color="${light_grey_RGB}" stl_ext="" reflect="1" />
  
  <!-- Joints -->
  <xacro:fixed_pelvis_to_vectorNav />
  <xacro:fixed_pelvis_to_abduction side="left" reflect="1"/>
  <xacro:hip_abduction side="left"/>
  
  <!-- Transmissions -->
  <xacro:hip_abduction_trans side="left"/>
  
  <!-- Link Definitions-->
  <xacro:macro name="vectorNav">
    <link name="vectorNav">
      <inertial>
            <origin xyz="0 0 0" rpy="0 0 0"/>
            <mass value="0.1" />
            <inertia ixx="0.000166666666667" ixy="0.0" ixz="0.0" iyy="0.000166666666667" iyz="0.0" izz="0.000166666666667"/>
        </inertial>
        <collision>
            <origin xyz="0 0 0" rpy="0 0 0"/>
            <geometry>
                <box size="0.1 0.1 0.1"/>
            </geometry>
        </collision>
        <visual>
            <origin rpy="0.0 0 0" xyz="0 0 0"/>
            <geometry>
                <box size="0.1 0.1 0.1"/>
            </geometry>
        </visual>
    </link>
    
      <gazebo reference="vectorNav">
    <kp>100000000.0</kp>
    <kd>10.0</kd>
    <mu1>0.1</mu1>
    <mu2>0.1</mu2>
    <fdir1>1 0 0</fdir1>
    <maxVel>10.0</maxVel>
    <minDepth>0.0005</minDepth>
    <material>Gazebo/Green</material>
  </gazebo>
  </xacro:macro> 
  
  <xacro:macro name="pelvis" params="cname color">
    <link name="pelvis">
      <inertial>
        <origin xyz=".0507 0 .0284" rpy="0 0 0"/>
        <mass value="10.33" />
		<inertia ixx=".0942" ixy=".000169" ixz=".015" iyy=".084" iyz=".000516" izz=".113" />
      </inertial>
      <collision>
            <origin xyz="0 0 0" rpy="0 0 0" />
        <geometry>
          <mesh filename="package://cassie_description/meshes/pelvis.stl" scale="1 1 1"/>
        </geometry>
        </collision>
      <visual>
        <origin xyz="0 0 0" rpy="0 0 0" />
        <geometry>
          <mesh filename="package://cassie_description/meshes/pelvis.stl" scale="1 1 1"/>
        </geometry>
        <material name="${cname}">
          <color rgba="${color}" />
        </material>
      </visual>
    </link>
    
    <gazebo reference="pelvis">
    <kp>100000000.0</kp>
    <kd>10.0</kd>
    <mu1>0.1</mu1>
    <mu2>0.1</mu2>
    <fdir1>1 0 0</fdir1>
    <maxVel>10.0</maxVel>
    <minDepth>0.0005</minDepth>
    <material>Gazebo/Red</material>
  </gazebo>
  </xacro:macro>
  
  <xacro:macro name="pelvis_abduction" params="side cname color stl_ext">
    <link name="${side}_pelvis_abduction">
      <inertial>
        <origin xyz="0 0 0" rpy="0 0 0"/>
        <mass value="1.82" />
        <!-- Placed Box aprox because its needed for gazebo to work -->
        <inertia ixx="0.00367306333333" ixy="0" ixz="0" iyy="0.00309085291667" iyz="0" izz="0.00329105291667" />
      </inertial>
      <collision>
            <origin xyz="0 0 0" rpy="0 0 0" />
        <geometry>
          <mesh filename="package://cassie_description/meshes/abduction${stl_ext}.stl" scale="1 1 1"/>
        </geometry>
        </collision>
      <visual>
        <origin xyz="0 0 0" rpy="0 0 0" />
        <geometry>
          <mesh filename="package://cassie_description/meshes/abduction${stl_ext}.stl" scale="1 1 1"/>
        </geometry>
        <material name="${cname}">
          <color rgba="${color}" />
        </material>
      </visual>
    </link>
    
    <gazebo reference="${side}_pelvis_abduction">
    <kp>100000000.0</kp>
    <kd>10.0</kd>
    <mu1>0.1</mu1>
    <mu2>0.1</mu2>
    <fdir1>1 0 0</fdir1>
    <maxVel>10.0</maxVel>
    <minDepth>0.0005</minDepth>
    <material>Gazebo/Red</material>
    </gazebo>
    
  </xacro:macro>
  
  <xacro:macro name="pelvis_rotation" params="side cname color stl_ext reflect">
    <link name="${side}_pelvis_rotation">
      <inertial>
        <origin xyz=".0257 ${reflect*.0001} .0179" rpy="0 0 0"/>
        <mass value="1.82" />
        <inertia ixx=".00272" ixy="${reflect*.000000703}" ixz=".00000153" iyy=".00559" iyz="${reflect*.00000261}" izz=".004640" />
      </inertial>
      <collision>
            <origin xyz="0 0 0" rpy="0 0 0" />
        <geometry>
          <mesh filename="package://cassie_description/meshes/yaw${stl_ext}.stl" scale="1 1 1"/>
        </geometry>
        </collision>
      <visual>
        <origin xyz="0 0 0" rpy="0 0 0" />
        <geometry>
          <mesh filename="package://cassie_description/meshes/yaw${stl_ext}.stl" scale="1 1 1"/>
        </geometry>
        <material name="${cname}">
          <color rgba="${color}" />
        </material>
      </visual>
    </link>
    
    <gazebo reference="${side}_pelvis_rotation">
    <kp>100000000.0</kp>
    <kd>10.0</kd>
    <mu1>0.1</mu1>
    <mu2>0.1</mu2>
    <fdir1>1 0 0</fdir1>
    <maxVel>10.0</maxVel>
    <minDepth>0.0005</minDepth>
    <material>Gazebo/Blue</material>
    </gazebo>
    
  </xacro:macro>

  <!-- Joint Definitions -->
  <xacro:macro name="fixed_pelvis_to_vectorNav">
    <joint name="fixed_pelvis_to_vectorNav" type="fixed">
      <origin xyz="0.03155 0 -0.07996" rpy="0 0 0"/>
      <parent link="pelvis" />
      <child link="vectorNav" />
    </joint>
  </xacro:macro>
  
  <xacro:macro name="fixed_pelvis_to_abduction" params="side reflect">
    <joint name="fixed_${side}" type="fixed">
      <origin xyz="0.021 ${reflect*0.135} 0" rpy="0 ${pi/2} 0"/>
      <parent link="pelvis" />
      <child link="${side}_pelvis_abduction" />
    </joint>
  </xacro:macro>
  
  <xacro:macro name="hip_abduction" params="side">
    <joint name="hip_abduction_${side}" type="continuous">
      <origin xyz="0 0 -0.07" rpy="0 ${-pi/2} 0"/>
      <axis xyz="1 0 0"/>
      <parent link="${side}_pelvis_abduction" />
      <child link="${side}_pelvis_rotation" />
	  <xacro:if value="${side == 'left'}">
	    <limit lower="-0.2618" upper="0.3927" effort="4.5" velocity="12.1475" />
	  </xacro:if>
	  <xacro:if value="${side == 'right'}">
	    <limit lower="-0.3927" upper="0.2618" effort="4.5" velocity="12.1475" />
	  </xacro:if>	  
    </joint>
  </xacro:macro>
  
  <!-- Transmission Definitions -->
  <xacro:macro name="hip_abduction_trans" params="side">
    <transmission name="hip_abduction_trans_${side}">
        <type>transmission_interface/SimpleTransmission</type>
        <joint name="hip_abduction_${side}">
            <hardwareInterface>hardware_interface/EffortJointInterface</hardwareInterface>
        </joint>
        <actuator name="hip_abduction_motor_${side}">
            <hardwareInterface>hardware_interface/EffortJointInterface</hardwareInterface>
            <mechanicalReduction>25</mechanicalReduction>
        </actuator>
    </transmission>
    
  </xacro:macro>
  
  <gazebo>
        <plugin name="gazebo_ros_control" 
                filename="libgazebo_ros_control.so">
          <robotNamespace>/cassie</robotNamespace>
          <robotParam>/cassie_robot_description</robotParam>
          <robotSimType>gazebo_ros_control/DefaultRobotHWSim</robotSimType>
        </plugin>
  </gazebo>

</robot>
