<?xml version="1.0"?>
<!-- Author: Ross Hartley
	 Email:  rosshart@umich.edu
     Date:   04/24/2016   -->
<robot name="cassie" xmlns:xacro="http://ros.org/wiki/xacro">

  <!-- Properties -->
  <xacro:property name="black_RGB" value="0.1 0.1 0.1 1" />
  <xacro:property name="grey_RGB" value="0.35 0.35 0.35 1" />
  <xacro:property name="orange_RGB" value=".9569 .5372 .2588 1" />
  <xacro:property name="blue_RGB" value=".0157 .1176 .2588 1" />
  <xacro:property name="maize_RGB" value=".9451 .7686 0 1" />
  <xacro:property name="light_grey_RGB" value="0.75 0.75 0.75 1" />

  <!-- Link Definitions-->
  <xacro:macro name="vectorNav">
    <link name="vectorNav">
      <inertial>
        <origin xyz="0 0 0" rpy="0 0 0" />
        <mass value="0.01" />
        <inertia ixx="1.66666666667e-07" ixy="0.0" ixz="0.0" iyy="1.66666666667e-07" iyz="0.0" izz="1.66666666667e-07" />
      </inertial>
      <collision>
        <origin xyz="0 0 0" rpy="0 0 0" />
        <geometry>
          <box size="0.01 0.01 0.01" />
        </geometry>
      </collision>
      <visual>
        <origin rpy="0.0 0 0" xyz="0 0 0" />
        <geometry>
          <box size="0.1 0.1 0.1" />
        </geometry>
      </visual>
    </link>

    <gazebo reference="vectorNav">
      <kp>100000000.0</kp>
      <kd>10.0</kd>
      <mu1>0.1</mu1>
      <mu2>0.1</mu2>
      <fdir1>1 0 0</fdir1>
      <maxVel>10.0</maxVel>
      <minDepth>0.0005</minDepth>
      <material>Gazebo/Green</material>
    </gazebo>
  </xacro:macro>

  <xacro:macro name="pelvis" params="cname color">
    <link name="pelvis">
      <inertial>
        <origin xyz=".0507 0 .0284" rpy="0 0 0" />
        <mass value="10.33" />
        <inertia ixx=".0942" ixy=".000169" ixz=".015" iyy=".084" iyz=".000516" izz=".113" />
      </inertial>
      <collision>
        <origin xyz="0 0 0" rpy="0 0 0" />
        <geometry>
          <mesh filename="package://cassie_description/meshes/pelvis.stl" scale="1 1 1" />
        </geometry>
      </collision>
      <visual>
        <origin xyz="0 0 0" rpy="0 0 0" />
        <geometry>
          <mesh filename="package://cassie_description/meshes/pelvis.stl" scale="1 1 1" />
        </geometry>
        <material name="${cname}">
          <color rgba="${color}" />
        </material>
      </visual>
    </link>

    <gazebo reference="pelvis">
      <kp>100000000.0</kp>
      <kd>10.0</kd>
      <mu1>0.1</mu1>
      <mu2>0.1</mu2>
      <fdir1>1 0 0</fdir1>
      <maxVel>10.0</maxVel>
      <minDepth>0.0005</minDepth>
      <material>Gazebo/Red</material>
    </gazebo>
  </xacro:macro>

  <xacro:macro name="pelvis_abduction" params="side cname color stl_ext">
    <link name="${side}_pelvis_abduction">
      <inertial>
        <origin xyz="0 0 0" rpy="0 0 0" />
        <mass value="1.82" />
        <!-- Placed Box aprox because its needed for gazebo to work -->
        <inertia ixx="0.00367306333333" ixy="0" ixz="0" iyy="0.00309085291667" iyz="0" izz="0.00329105291667" />
      </inertial>
      <collision>
        <origin xyz="0 0 0" rpy="0 0 0" />
        <geometry>
          <mesh filename="package://cassie_description/meshes/abduction${stl_ext}.stl" scale="1 1 1" />
        </geometry>
      </collision>
      <visual>
        <origin xyz="0 0 0" rpy="0 0 0" />
        <geometry>
          <mesh filename="package://cassie_description/meshes/abduction${stl_ext}.stl" scale="1 1 1" />
        </geometry>
        <material name="${cname}">
          <color rgba="${color}" />
        </material>
      </visual>
    </link>

    <gazebo reference="${side}_pelvis_abduction">
      <kp>100000000.0</kp>
      <kd>10.0</kd>
      <mu1>0.1</mu1>
      <mu2>0.1</mu2>
      <fdir1>1 0 0</fdir1>
      <maxVel>10.0</maxVel>
      <minDepth>0.0005</minDepth>
      <material>Gazebo/Red</material>
    </gazebo>

  </xacro:macro>

  <xacro:macro name="pelvis_rotation" params="side cname color stl_ext reflect">
    <link name="${side}_pelvis_rotation">
      <inertial>
        <origin xyz=".0257 ${reflect*.0001} .0179" rpy="0 0 0" />
        <mass value="1.82" />
        <inertia ixx=".00272" ixy="${reflect*.000000703}" ixz=".00000153" iyy=".00559" iyz="${reflect*.00000261}" izz=".004640" />
      </inertial>
      <collision>
        <origin xyz="0 0 0" rpy="0 0 0" />
        <geometry>
          <mesh filename="package://cassie_description/meshes/yaw${stl_ext}.stl" scale="1 1 1" />
        </geometry>
      </collision>
      <visual>
        <origin xyz="0 0 0" rpy="0 0 0" />
        <geometry>
          <mesh filename="package://cassie_description/meshes/yaw${stl_ext}.stl" scale="1 1 1" />
        </geometry>
        <material name="${cname}">
          <color rgba="${color}" />
        </material>
      </visual>
    </link>

    <gazebo reference="${side}_pelvis_rotation">
      <kp>100000000.0</kp>
      <kd>10.0</kd>
      <mu1>0.1</mu1>
      <mu2>0.1</mu2>
      <fdir1>1 0 0</fdir1>
      <maxVel>10.0</maxVel>
      <minDepth>0.0005</minDepth>
      <material>Gazebo/Blue</material>
    </gazebo>

  </xacro:macro>


  <xacro:macro name="hip" params="side cname color stl_ext">
    <link name="${side}_hip">
      <inertial>
        <origin xyz="-.0557 0 0" rpy="0 0 0" />
        <mass value="1.17" />
        <inertia ixx=".000842" ixy=".000000246" ixz="-.000000625" iyy=".006080" iyz="-.00000004" izz=".006440" />
      </inertial>
      <collision>
        <origin xyz="0 0 0" rpy="0 0 0" />
        <geometry>
          <mesh filename="package://cassie_description/meshes/hip${stl_ext}.stl" scale="1 1 1" />
        </geometry>
      </collision>
      <visual>
        <origin xyz="0 0 0" rpy="0 0 0" />
        <geometry>
          <mesh filename="package://cassie_description/meshes/hip${stl_ext}.stl" scale="1 1 1" />
        </geometry>
        <material name="${cname}">
          <color rgba="${color}" />
        </material>
      </visual>
    </link>

    <gazebo reference="${side}_hip">
      <kp>100000000.0</kp>
      <kd>10.0</kd>
      <mu1>0.1</mu1>
      <mu2>0.1</mu2>
      <fdir1>1 0 0</fdir1>
      <maxVel>10.0</maxVel>
      <minDepth>0.0005</minDepth>
      <material>Gazebo/Blue</material>
    </gazebo>
  </xacro:macro>


  <xacro:macro name="thigh" params="side cname color stl_ext reflect">
    <link name="${side}_thigh">
      <inertial>
        <origin xyz=".0598 .0001 ${reflect*-.0358}" rpy="0 0 0" />
        <mass value="5.52" />
        <inertia ixx=".018" ixy=".000284" ixz="${reflect*-.0117}" iyy=".0563" iyz="${reflect*-.0000193}" izz=".0498" />
      </inertial>
      <collision>
        <origin xyz="0 0 0" rpy="0 0 0" />
        <geometry>
          <mesh filename="package://cassie_description/meshes/thigh${stl_ext}.stl" scale="1 1 1" />
        </geometry>
      </collision>
      <visual>
        <origin xyz="0 0 0" rpy="0 0 0" />
        <geometry>
          <mesh filename="package://cassie_description/meshes/thigh${stl_ext}.stl" scale="1 1 1" />
        </geometry>
        <material name="${cname}">
          <color rgba="${color}" />
        </material>
      </visual>
    </link>

    <gazebo reference="${side}_thigh">
      <kp>100000000.0</kp>
      <kd>10.0</kd>
      <mu1>0.1</mu1>
      <mu2>0.1</mu2>
      <fdir1>1 0 0</fdir1>
      <maxVel>10.0</maxVel>
      <minDepth>0.0005</minDepth>
      <material>Gazebo/Blue</material>
    </gazebo>
  </xacro:macro>


  <xacro:macro name="knee" params="side cname color stl_ext reflect">
    <link name="${side}_knee">
      <inertial>
        <origin xyz=".023 .0321 ${reflect*-.0022}" rpy="0 0 0" />
        <mass value=".758" />
        <inertia ixx=".002160" ixy=".000956" ixz="${reflect*.00000284}" iyy=".00144" iyz="${reflect*.000000739}" izz=".00334" />
      </inertial>
      <collision>
        <origin xyz="0 0 0" rpy="0 0 0" />
        <geometry>
          <mesh filename="package://cassie_description/meshes/knee-output${stl_ext}.stl" scale="1 1 1" />
        </geometry>
      </collision>
      <visual>
        <origin xyz="0 0 0" rpy="0 0 0" />
        <geometry>
          <mesh filename="package://cassie_description/meshes/knee-output${stl_ext}.stl" scale="1 1 1" />
        </geometry>
        <material name="${cname}">
          <color rgba="${color}" />
        </material>
      </visual>
    </link>

    <gazebo reference="${side}_knee">
      <kp>100000000.0</kp>
      <kd>10.0</kd>
      <mu1>0.1</mu1>
      <mu2>0.1</mu2>
      <fdir1>1 0 0</fdir1>
      <maxVel>10.0</maxVel>
      <minDepth>0.0005</minDepth>
      <material>Gazebo/Green</material>
    </gazebo>
  </xacro:macro>


  <xacro:macro name="shin" params="side cname color stl_ext reflect">
    <link name="${side}_shin">
      <inertial>
        <origin xyz=".1834 .0012 ${reflect*.0002}" rpy="0 0 0" />
        <mass value=".577" />
        <inertia ixx=".000360" ixy=".000334" ixz="${reflect*-.000000194}" iyy=".0341" iyz="${reflect*.000000265}" izz=".0341" />
      </inertial>
      <collision>
        <origin xyz="0 0 0" rpy="0 0 0" />
        <geometry>
          <mesh filename="package://cassie_description/meshes/shin-bone${stl_ext}.stl" scale="1 1 1" />
        </geometry>
      </collision>
      <visual>
        <origin xyz="0 0 0" rpy="0 0 0" />
        <geometry>
          <mesh filename="package://cassie_description/meshes/shin-bone${stl_ext}.stl" scale="1 1 1" />
        </geometry>
        <material name="${cname}">
          <color rgba="${color}" />
        </material>
      </visual>
    </link>

    <gazebo reference="${side}_shin">
      <kp>100000000.0</kp>
      <kd>10.0</kd>
      <mu1>0.1</mu1>
      <mu2>0.1</mu2>
      <fdir1>1 0 0</fdir1>
      <maxVel>10.0</maxVel>
      <minDepth>0.0005</minDepth>
      <material>Gazebo/Green</material>
    </gazebo>
  </xacro:macro>

  <xacro:macro name="tarsus" params="side cname color stl_ext reflect">
    <link name="${side}_tarsus">
      <inertial>
        <origin xyz=".1105 -.0306 ${reflect*-.0013}" rpy="0 0 0" />
        <mass value=".782" />
        <inertia ixx=".00113" ixy="-.00288" ixz="${reflect*-.0000633}" iyy=".0231" iyz="${reflect*.0000362}" izz=".0239" />
      </inertial>
      <collision>
        <origin xyz="0 0 0" rpy="0 0 0" />
        <geometry>
          <mesh filename="package://cassie_description/meshes/tarsus${stl_ext}.stl" scale="1 1 1" />
        </geometry>
      </collision>
      <visual>
        <origin xyz="0 0 0" rpy="0 0 0" />
        <geometry>
          <mesh filename="package://cassie_description/meshes/tarsus${stl_ext}.stl" scale="1 1 1" />
        </geometry>
        <material name="${cname}">
          <color rgba="${color}" />
        </material>
      </visual>
    </link>

    <gazebo reference="${side}_tarsus">
      <kp>100000000.0</kp>
      <kd>10.0</kd>
      <mu1>0.1</mu1>
      <mu2>0.1</mu2>
      <fdir1>1 0 0</fdir1>
      <maxVel>10.0</maxVel>
      <minDepth>0.0005</minDepth>
      <material>Gazebo/Green</material>
    </gazebo>
  </xacro:macro>


  <xacro:macro name="toe" params="side cname color stl_ext reflect">
    <link name="${side}_toe">
      <inertial>
        <origin xyz=".0047 .0275 ${reflect*-.0001}" rpy="0 0 0" />
        <mass value=".15" />
        <inertia ixx=".000287" ixy="-.0000986" ixz="${reflect*-.00000146}" iyy=".000171" iyz="${reflect*.000000172}" izz=".000449" />
      </inertial>
      <collision>
        <origin xyz="0 0 0" rpy="0 0 0" />
        <geometry>
          <mesh filename="package://cassie_description/meshes/toe${stl_ext}.stl" scale="1 1 1" />
        </geometry>
      </collision>
      <visual>
        <origin xyz="0 0 0" rpy="0 0 0" />
        <geometry>
          <mesh filename="package://cassie_description/meshes/toe${stl_ext}.stl" scale="1 1 1" />
        </geometry>
        <material name="${cname}">
          <color rgba="${color}" />
        </material>
      </visual>
    </link>

    <gazebo reference="${side}_toe">
      <kp>100000000.0</kp>
      <kd>10.0</kd>
      <mu1>0.1</mu1>
      <mu2>0.1</mu2>
      <fdir1>1 0 0</fdir1>
      <maxVel>10.0</maxVel>
      <minDepth>0.0005</minDepth>
      <material>Gazebo/Green</material>
    </gazebo>
  </xacro:macro>

  <!-- Joint Definitions -->
  <xacro:macro name="fixed_pelvis_to_vectorNav">
    <joint name="fixed_pelvis_to_vectorNav" type="fixed">
      <origin xyz="0.03155 0 -0.07996" rpy="0 0 0" />
      <parent link="pelvis" />
      <child link="vectorNav" />
    </joint>
  </xacro:macro>

  <xacro:macro name="fixed_pelvis_to_abduction" params="side reflect">
    <joint name="fixed_${side}" type="fixed">
      <origin xyz="0.021 ${reflect*0.135} 0" rpy="0 ${pi/2} 0" />
      <parent link="pelvis" />
      <child link="${side}_pelvis_abduction" />
    </joint>
  </xacro:macro>

  <xacro:macro name="hip_abduction" params="side">
    <joint name="hip_abduction_${side}" type="revolute">
      <origin xyz="0 0 -0.07" rpy="0 ${-pi/2} 0" />
      <axis xyz="1 0 0" />
      <parent link="${side}_pelvis_abduction" />
      <child link="${side}_pelvis_rotation" />
      <xacro:if value="${side == 'left'}">
        <limit lower="0.0" upper="1" effort="2000.0" velocity="12.1475" />
      </xacro:if>
      <xacro:if value="${side == 'right'}">
        <limit lower="0.0" upper="1" effort="2000.0" velocity="12.1475" />
      </xacro:if>
    </joint>
  </xacro:macro>

  <xacro:macro name="hip_rotation" params="side">
    <joint name="hip_rotation_${side}" type="revolute">
      <origin xyz="0 0 -0.09" rpy="0 ${pi/2} ${-pi/2}" />
      <axis xyz="-1 0 0" />
      <parent link="${side}_pelvis_rotation" />
      <child link="${side}_hip" />
      <limit lower="0.0" upper="1" effort="2000.0" velocity="12.1475" />
    </joint>
  </xacro:macro>
  <xacro:macro name="hip_flexion" params="side">
    <joint name="hip_flexion_${side}" type="revolute">
      <origin xyz="0 0 0" rpy="0 0 0.7" />
      <axis xyz="0 0 1" />
      <parent link="${side}_hip" />
      <child link="${side}_thigh" />
      <limit lower="0" upper="1" effort="2000.0" velocity="8.5085" />
    </joint>
  </xacro:macro>
  <xacro:macro name="knee_joint" params="side reflect">
    <joint name="knee_joint_${side}" type="revolute">
      <origin xyz="0.12 0 ${reflect*0.0045}" rpy="0 0 -1.75" />
      <axis xyz="0 0 1" />
      <parent link="${side}_thigh" />
      <child link="${side}_knee" />
      <limit lower="0.0" upper="1" effort="2000.0" velocity="8.5085" />
    </joint>
  </xacro:macro>
  <xacro:macro name="knee_to_shin" params="side">
    <joint name="knee_to_shin_${side}" type="revolute">
      <origin xyz="0.0607 0.0474 0" rpy="0 0 -0.7" />
      <axis xyz="0 0 1" />
      <parent link="${side}_knee" />
      <child link="${side}_shin" />
      <limit lower="0" upper="0" effort="2000.0" velocity="8.5085" />
    </joint>
  </xacro:macro>
  <xacro:macro name="ankle_joint" params="side">
    <joint name="ankle_joint_${side}" type="revolute">
      <origin xyz="0.4348 0.02 0" rpy="0 0 1.5" />
      <axis xyz="0 0 1" />
      <parent link="${side}_shin" />
      <child link="${side}_tarsus" />
      <limit lower="0" upper="0" effort="2000.0" velocity="8.5085" />
    </joint>
  </xacro:macro>

  <xacro:macro name="toe_joint" params="side">
    <joint name="toe_joint_${side}" type="revolute">
      <origin xyz="0.408 -0.04 0" rpy="0 0 -1.5" />
      <axis xyz="0 0 1" />
      <parent link="${side}_tarsus" />
      <child link="${side}_toe" />
      <limit lower="0" upper="1" effort="2000.0" velocity="11.5192" />
    </joint>
  </xacro:macro>


  <!-- Transmission Definitions -->
  <xacro:macro name="hip_abduction_trans" params="side">
    <transmission name="hip_abduction_trans_${side}">
      <type>transmission_interface/SimpleTransmission</type>
      <joint name="hip_abduction_${side}">
        <hardwareInterface>hardware_interface/EffortJointInterface</hardwareInterface>
      </joint>
      <actuator name="hip_abduction_motor_${side}">
        <hardwareInterface>hardware_interface/EffortJointInterface</hardwareInterface>
        <mechanicalReduction>1</mechanicalReduction>
      </actuator>
    </transmission>
  </xacro:macro>

  <xacro:macro name="hip_rotation_trans" params="side">
    <transmission name="hip_rotation_trans_${side}">
      <type>transmission_interface/SimpleTransmission</type>
      <joint name="hip_rotation_${side}">
        <hardwareInterface>hardware_interface/EffortJointInterface</hardwareInterface>
      </joint>
      <actuator name="hip_rotation_motor_${side}">
        <hardwareInterface>hardware_interface/EffortJointInterface</hardwareInterface>
        <mechanicalReduction>1</mechanicalReduction>
      </actuator>
    </transmission>
  </xacro:macro>


  <xacro:macro name="hip_flexion_trans" params="side">
    <transmission name="hip_flexion_trans_${side}">
      <type>transmission_interface/SimpleTransmission</type>
      <joint name="hip_flexion_${side}">
        <hardwareInterface>hardware_interface/EffortJointInterface</hardwareInterface>
      </joint>
      <actuator name="hip_flexion_motor_${side}">
        <hardwareInterface>hardware_interface/EffortJointInterface</hardwareInterface>
        <mechanicalReduction>16</mechanicalReduction>
      </actuator>
    </transmission>
  </xacro:macro>


  <xacro:macro name="knee_joint_trans" params="side">
    <transmission name="knee_joint_trans_${side}">
      <type>transmission_interface/SimpleTransmission</type>
      <joint name="knee_joint_${side}">
        <hardwareInterface>hardware_interface/EffortJointInterface</hardwareInterface>
      </joint>
      <actuator name="knee_joint_motor_${side}">
        <hardwareInterface>hardware_interface/EffortJointInterface</hardwareInterface>
        <mechanicalReduction>16</mechanicalReduction>
      </actuator>
    </transmission>
  </xacro:macro>


  <xacro:macro name="toe_joint_trans" params="side">
    <transmission name="toe_joint_trans_${side}">
      <type>transmission_interface/SimpleTransmission</type>
      <joint name="toe_joint_${side}">
        <hardwareInterface>hardware_interface/EffortJointInterface</hardwareInterface>
      </joint>
      <actuator name="toe_joint_motor_${side}">
        <hardwareInterface>hardware_interface/EffortJointInterface</hardwareInterface>
        <mechanicalReduction>50</mechanicalReduction>
      </actuator>
    </transmission>


  </xacro:macro>
  <!-- Links -->
  <xacro:vectorNav />
  <xacro:pelvis cname="grey" color="${grey_RGB}" />
  <xacro:pelvis_abduction side="left" cname="light_grey" color="${light_grey_RGB}" stl_ext="" />
  <xacro:pelvis_rotation side="left" cname="light_grey" color="${light_grey_RGB}" stl_ext="" reflect="1" />
  <xacro:hip side="left" cname="light_grey" color="${light_grey_RGB}" stl_ext="" />
  <xacro:thigh side="left" cname="light_grey" color="${light_grey_RGB}" stl_ext="" reflect="1" />
  <xacro:knee side="left" cname="grey" color="${grey_RGB}" stl_ext="" reflect="1" />
  <xacro:shin side="left" cname="grey" color="${grey_RGB}" stl_ext="" reflect="1" />
  <xacro:tarsus side="left" cname="grey" color="${grey_RGB}" stl_ext="" reflect="1" />
  <xacro:toe side="left" cname="light_grey" color="${light_grey_RGB}" stl_ext="" reflect="1" />
  <xacro:pelvis_abduction side="right" cname="light_grey" color="${light_grey_RGB}" stl_ext="_mirror" />
  <xacro:pelvis_rotation side="right" cname="light_grey" color="${light_grey_RGB}" stl_ext="_mirror" reflect="-1" />
  <xacro:hip side="right" cname="light_grey" color="${light_grey_RGB}" stl_ext="_mirror" />
  <xacro:thigh side="right" cname="light_grey" color="${light_grey_RGB}" stl_ext="_mirror" reflect="-1" />
  <xacro:knee side="right" cname="grey" color="${grey_RGB}" stl_ext="_mirror" reflect="-1" />
  <xacro:shin side="right" cname="grey" color="${grey_RGB}" stl_ext="_mirror" reflect="-1" />
  <xacro:tarsus side="right" cname="grey" color="${grey_RGB}" stl_ext="_mirror" reflect="-1" />
  <xacro:toe side="right" cname="light_grey" color="${light_grey_RGB}" stl_ext="_mirror" reflect="-1" />

  <!-- Joints -->
  <xacro:fixed_pelvis_to_vectorNav />
  <xacro:fixed_pelvis_to_abduction side="left" reflect="1" />
  <xacro:hip_abduction side="left" />
  <xacro:hip_rotation side="left" />
  <xacro:hip_flexion side="left" />
  <xacro:knee_joint side="left" reflect="1" />
  <xacro:knee_to_shin side="left" />
  <xacro:ankle_joint side="left" />
  <xacro:toe_joint side="left" />
  <xacro:fixed_pelvis_to_abduction side="right" reflect="-1" />
  <xacro:hip_abduction side="right" />
  <xacro:hip_rotation side="right" />
  <xacro:hip_flexion side="right" />
  <xacro:knee_joint side="right" reflect="-1" />
  <xacro:knee_to_shin side="right" />
  <xacro:ankle_joint side="right" />
  <xacro:toe_joint side="right" />

  <!-- Transmissions -->
  <xacro:hip_abduction_trans side="left" />
  <xacro:hip_rotation_trans side="left" />
  <xacro:hip_flexion_trans side="left" />
  <xacro:knee_joint_trans side="left" />
  <xacro:toe_joint_trans side="left" />
  <xacro:hip_abduction_trans side="right" />
  <xacro:hip_rotation_trans side="right" />
  <xacro:hip_flexion_trans side="right" />
  <xacro:knee_joint_trans side="right" />
  <xacro:toe_joint_trans side="right" />

  <gazebo>
    <plugin name="gazebo_ros_control" filename="libgazebo_ros_control.so">
      <robotNamespace>/cassie</robotNamespace>
      <robotParam>/cassie_robot_description</robotParam>
      <robotSimType>gazebo_ros_control/DefaultRobotHWSim</robotSimType>
    </plugin>
  </gazebo>


</robot>